Workbook
Name _1g51s3qemn8t: 'ELI-DL URI components'!$B$74
Name _1rtyz16hkql9: 'ELI-DL URI components'!$B$112
Name _65ifpjxamdc9: 'ELI-DL URI components'!$B$41
Name _81ywfesawyfo: 'ELI-DL URI components'!$B$11
Name _d8lcnsdcmwif: 'ELI-DL URI components'!$B$1
Name _gebdzw3vhd15: 'ELI-DL URI components'!$B$67
Name _hnvwax436uja: 'ELI-DL URI components'!$B$105
Name _mamtjvujatl7: 'ELI-DL URI components'!$B$25
Name _n5uzx5ky6uln: 'ELI-DL URI components'!$B$48
Name _n9rj8zpyg5nh: 'ELI-DL URI components'!$B$99
Name _vd6e4u8787t9: 'ELI-DL URI components'!$B$30
Name _wtvsc88dv05u: 'ELI-DL URI components'!$B$60
Name _xdcur1jrrehc: 'ELI-DL URI components'!$B$34
Name Print_Area_0: 'Schema.org Legislation (Mapping'!$A$4:$A$129

Sheet Inhaltsverzeichnis
B1: Inhaltsverzeichnis
B5: Name | C5: Description | D5: Type | E5: Source | F5: Version | G5: Release Date | H5: Compatibility
A6: 1 | B6: Rechtsgrundlagen | C6: Schlussfolgerungen des Rates mit einem Aufruf zur Einführung des European Legislation Identifier (ELI) (2012/C 325/02) | D6: law | E6: https://eur-lex.europa.eu/legal-content/DE/TXT/PDF/?uri=CELEX:52012XG1026(01) | G6: 2012
A7: 2 | B7: ELI Release | D7: ZIP | E7: https://op.europa.eu/en/web/eu-vocabularies/dataset/-/resource?uri=http://publications.europa.eu/resource/dataset/eli | F7: 1.5
A8: 2.1 | B8: Implementing ELI | C8: webpage providing documentation and tools for countries and organisations to support their implementation of ELI: (1) Guides and specifications, (2) Extension standards (ELI-DL, ELI-I) (2) Ontology, (4) EU Authority tables (3) XML Schema, (5) Schema.org Mapping, (6) Tools | D8: Webpage | E8: https://eur-lex.europa.eu/content/eli-register/implementing_eli.html | F8: n/a | G8: n/a | H8: n/a
A9: 2.2 | B9: ELI Technical implementation guide (third edition) | C9: ELI URI identifiers ELI ontology / data model (v.1.4.) ELI publication (metadata publishing) ELI synchronisation (Pillar IV specifications) ELI use-cases (in annex) | D9: PDF | F9: 1.4 | H9: This guide refers to the version 1.4 of the ELI ontology
A10: 2.3 | B10: ELI Good practices and guidelines (third edition) | D10: PDF | G10: 45139
A11: 3 | B11: Schema.org - Publication | C11: Mapping to PublicationIssue | D11: Webpage
A12: 4.1 | B12: ELI ontology for draft legislation (ELI-DL) Release | C12: ELI-DL extension standard: ELI-DL URI components ELI-DL OWL ontology ELI-DL diagrams ELI-DL examples | D12: Webpage | E12: https://interoperable-europe.ec.europa.eu/collection/eli-european-legislation-identifier/solution/eli-ontology-draft-legislation-eli-dl | F12: 3 | G12: 45240 | H12: This version is not backward-compatible with the previous version on the modelling of Votes. This version relies on ELI ontology 1.5.
A13: 5 | B13: ELI Impact (ELI-I) Release | C13: ELI-I

Sheet ELI Rechtsgrundlagen
B1: Elemente des ELI (Rechtsgrundlagen) | K1: Schweizer Entsprechung
B2: Schlussfolgerungen des Rates mit einem Aufruf zur Einführung des European Legislation Identifier (ELI) (2012/C 325/02)
B3: Source: https://eur-lex.europa.eu/legal-content/DE/TXT/PDF/?uri=CELEX:52012XG1026(01)
B5: Die folgenden Elemente des ELI können unabhängig voneinander implementiert werden:
A6: 1 | B6: Identifizierung der Rechtsvorschriften | C6: (URI)
A7: 2 | B7: Beschreibung aller Rechtsvorschriften | C7: (Metadaten und Ontologie)
A10: 1 | B10: Identifizierung der Rechtsvorschriften
B12: Der ELI verwendet URI (Unified Resource Identifier) im HTTP-Format zur spezifischen Identifizierung aller online verfügbaren Rechtsinformationen, die von amtlicher Seite in ganz Europa veröffentlicht werden. Diese URI werden formell über automatisch lesbare URI-Schematafeln (IETF RFC 6570) beschrieben und verwenden Bestandteile, die Semantiken sowohl aus juristischer wie aus Verbrauchersicht beinhalten. Jeder Mitgliedstaat erstellt seine eigenen, selbstbeschreibenden URI unter Verwendung der erwähnten Bestandteile und unter Berücksichtigung der spezifischen Spracherfordernisse. Alle Bestandteile sind optional und können auf Grundlage der nationalen Anforderungen ausgewählt werden; es ist keine feste Reihenfolge einzuhalten. Um den Austausch der Daten zu ermöglichen, muss die ausgewählte URISchematafel dokumentiert sein und den Mechanismus für URI-Schematafeln (siehe Beispiel) verwenden: | K12: Der Bund publiziert bereits Rechtsinformationen unter Verwendung der ELI URI, jedoch noch nicht alle. Bedingt durch den Föderalismus und weil auch innerhalb der Bundesverwaltung zum Teil dezentral Rechtsinformationen veröffentlicht werden, sind Rechtsinformationen zum Teil gar nicht oder nicht immer über ELI URI auffindbar. Insbesondere für die Kantone muss die ELI URI noch definiert werden Nicht alle
K13: 1 | M13: 2 | O13: 3 | Q13: 4
B14: Alle Bestandteile der ELI-Schematafel: | K14: Bund | M14: Kanton ZH | O14: Gemeinde … | Q14: Kanton ZH
B16: /eli/{jurisdiction}/{agent}/{sub-agent}/{year}/{month}/{day}/{type}/{sub-type}/{domain}/{natural-identifier}/{level-1}/.../{point-in-time}/{version}/{language} | K16: Vollbeispiel Bund | M16: Vollbeispiel Kanton ZH | O16: Vollbeispiel Gemeinde … | Q16: Vollbeispiel Kanton …
B18: Die einzelnen Bestandteile der ELI-Schematafel:
B20: Hierarchie (Vorschlag) | C20: Gruppe | D20: URI Bestandteil | E20: Comments | F20: Requirement | G20: Format (Recommendation) | H20: Additional Remarks
B21: 1 | C21: - | D21: /eli | F21: required | G21: n/a | H21: n/a | K21: eli | M21: eli | O21: eli | Q21: eli
B22: 2 | C22: Jurisdicition | D22: /{jurisdiction} | E22: Use of DCTERMS.ISO3166: 2 alpha country codes, e.g. ‘LU‘ For international organisations, the registered domain name can be used: e.g. ‘EU‘ or ‘WTO‘ | F22: optional (all components; order is flexible) | G22: 2 letter country code | K22: CH | M22: CH-ZH | O22: CH- | Q22: CH
B23: 3 | C23: Jurisdicition | D23: /{agent} | E23: Administrative hierarchical structure, e.g. federal States, constitutional court, parliament, usw. | F23: optional (all components; order is flexible) | G23: n/a | H23: codes for administrative hierarchical structures and substructures. Member States need to define their own values.
B24: 4 | C24: Jurisdicition | D24: /{sub-agent} | E24: Administrative hierarchical substructure, e.g. the responsible ministry | F24: optional (all components; order is flexible)
B25: 5 | C25: Reference | D25: /{year} | E25: YYYY Various interpretations allowed depending on countries‘ requirements, e.g. date of signature or date of publication, usw. | F25: optional (all components; order is flexible) | G25: {year}: 4 digits {month} and {day}: 2 digits | H25: The components don’t have to be used together (e.g. {year} can be used without {month} or {day})
B26: 6 | C26: Reference | D26: /{month} | E26: MM | F26: optional (all components; order is flexible)
B27: 7 | C27: Reference | D27: /{day} | E27: DD | F27: optional (all components; order is flexible)
B28: 8 | C28: Reference | D28: /{type} | E28: Nature of the act (law, decree, draft bill usw.). Various interpretations depending on countries‘ requirements | F28: optional (all components; order is flexible) | G28: n/a | H28: n/a
B29: 9 | C29: Reference | D29: /{sub-type} | E29: Subcategory of an act depending on countries‘ requirements (e.g. corrigendum | F29: optional (all components; order is flexible)
B30: 10 | C30: Reference | D30: /{domain} | E30: Can be used if acts are classified by themes, e.g. codes | F30: optional (all components; order is flexible) | H30: The technical implementation guide lists natural identifier first and then domain (inverse order)
B31: 11 | C31: Reference | D31: /{natural-identifier} | E31: Reference or number to distinguish an act of same nature signed or published on the same day | F31: optional (all components; order is flexible)
B32: 12* | C32: Subdivision | D32: /{level-n} | E32: Reference to a subdivision of an act and paragraph, e.g. Article 15 | F32: optional (all components; order is flexible) | G32: n/a (see also 2.2.3) | H32: When crafting ELIs for subdivisions, one need to combine a code to identify the subdivision type (section, article, paragraphs, etc.) and the number or identifier of the subdivision (1, A, 1.5.9, etc.). Concatenate the subdivision type and its number in a single component, using another separator, typically underscore “_”; e.g. /eli/law/2015/123/article_3/paragraph_2
B33: 13 | C33: Point in Time | D33: /{point-in-time} | E33: YYYYMMDD Version of the act as valid at a given date | F33: optional (all components; order is flexible) | G33: YYYYMMDD or YYYY-MM-DD | H33: Note that the Council conclusions inviting the introduction of the European Legislation Identifier only recommends YYYYMMDD but implementations using YYYY-MM-DD would still be valid.
B34: 14 | C34: Version | D34: /{version} | E34: To distinguish between original act or consolidated version | F34: optional (all components; order is flexible) | G34: n/a | H34: To distinguish between a base act or a consolidated version.
B35: 15 | C35: Language | D35: /{language} | E35: To differ different official expressions of the same act Use of DCTERMS.ISO3166: 3 alpha | F35: optional (all components; order is flexible) | G35: 3-letters language codes (ISO-639-1) | H35: Should I use 2-letter codes or 3-letter codes for the {language} component in ELI identifiers? ELI explicitly recommends using 3-letter codes for the {language} component when building ELI URIs (ISO-639-2). See the code list page for the list of language codes. That being said, implementations using 2-letters language codes would still be valid. It is expected in that case that an alias mechanism be implemented from one to the other.
B36: 16 | C36: Format | D36: /{format} | E36: n/a | F36: required | G36: A file format, like “pdf” or “html” | H36: Note that the Council conclusions inviting the introduction of the European Legislation does not list this component explicitly, but it is always part of the URIs to identify the eli:Format level.
B38: Note that ELI-DL also proposes additional URI components for ELI-DL URIs. These additional components are documented in the ELI-DL URI specification document
A43: 2 | B43: Beschreibung aller Rechtsvorschriften
B44: Ein strukturierter URI kann Rechtsakte bereits unter Verwendung eines Satzes fester Bestandteile kennzeichnen; die Zuweisung zusätzlicher Metadaten, die im Rahmen einer gemeinsamen Syntax festgelegt werden, legt darüber hinaus die Basis für die Förderung des Austauschs und der verbesserten Interoperabilität zwischen Rechtsinformationssystemen. Die Identifizierung der Metadaten zur Beschreibung der Kernmerkmale einer Ressource ermöglicht den Mitgliedstaaten die Wiederverwendung von anderen erstellter relevanter Informationen für eigene Zwecke, ohne hierfür weitere Informationssysteme bereitstellen zu müssen. Obgleich den Mitgliedstaaten freigestellt ist, ihre eigenen Metadaten-Schemata zu verwenden, wird ihnen nahegelegt, die ELI-Standards für Metadaten zu befolgen und anzuwenden; diese Standards verwenden gemeinsam genutzte aber erweiterbare Rechtsgrundlagenverzeichnisse, die es ermöglichen, spezifischen Anforderungen gerecht zu werden. Das ELI-Metadaten-Schema sollte zusammen mit spezifischen Metadaten-Schemata verwendet werden. Um den Datenaustausch möglichst effektiv zu gestalten, können ELI-Metadaten-Elemente gemäß der W3C-Empfehlung „RDFa in XHTML: Syntax and Processing“ in Serie geschaltet werden.
A46: a) | B46: Metadaten
B47: Level / Ontologie (FRBR) | C47: Field name | D47: Description | E47: Requirement | F47: Field identifier | G47: Cardinality | H47: Data type | I47: Comment
B48: Work / Legal Resource | C48: Unique identifier | D48: The number or string used to uniquely identify the resource ELI URI schema | E48: mandatory | F48: id_document | G48: 1…* | H48: String | I48: Siehe 1 Identifizierung der Rechtsvorschriften
B49: Work / Legal Resource | C49: URI schema | D49: Reference to the URI schema used | E49: mandatory | F49: uri_schema | G49: 1 | H49: String | I49: URI of the URI template schema
B50: Work / Legal Resource | C50: Local identifier | D50: Local identifier: the unique identifier used in a local reference system | E50: optional | F50: id_local | G50: 0…* | H50: String | I50: Act’s reference in the EU’s, country’s or region’s own terminolo­gy, e.g. CELEX id, national id
B51: Work / Legal Resource | C51: Type of ligeslation | D51: The type of a legal resource (e.g. directive, rè­glement grand ducal, law, règlement ministe­ riel, draft proposition, Parliamentary act uws.) | E51: recommended | F51: type_document | G51: 0…1 | H51: Authority table: resource types | I51: For European law based on authority table: Resource types = class names in the OP’s common data model (CDM). For national and regional laws specified on the appro­ priate level. Types of legislation are specific for each jurisdiction
B52: Work / Legal Resource | C52: Territorial application | D52: Geographical scope of applicability of the re­ source (e.g. EU, country/Member State, region us | E52: optional | G52: 0…* | H52: Authority table | I52: Individual administrative units, taxonomy of possible values to be defined (NUTS taxonomy, two or more levels)
B53: Work / Legal Resource | C53: Agent/authority | D53: Organisation(s) responsible for the resource The European institution, other bodies or Member State or regional bodies, who initiated/ adopted the legal resource (e.g. European Par­liament, Luxembourg Government, Rheinland- Pfalz Parliam etc.) | E53: recommended | G53: 0…* | H53: Authority table: corporate body | I53: Based on authority tables: Corporate bodies/countries, if necessary extended to cover regional agents. Record project
...

Sheet ELI
A1: ELI Ontology v.1.5
A2: Source: https://op.europa.eu/en/web/eu-vocabularies/dataset/-/resource?uri=http://publications.europa.eu/resource/dataset/eli
A4: File | B4: Description | C4: Reihenfolge
A5: ELI-validation-rules.zip | B5: contains shapes (recommended, core, ranges) | C5: 4-5
A6: ELI-release-note.docx | B6: ELI 1.5 Version Note (see below) | C6: 0
A7: catalog-v001.xml
A8: eli-sdo.ttl
A9: eli.owl
A10: ELI-sdo.xlsx | B10: ELI Schema Mapping | C10: 3
A11: eli-diagrams.pptx | B11: ELI Diagrams | C11: 2
A12: eli.xlsx | B12: ELI Ontology | C12: 1
A16: ELI 1.5 Version Note
A18: Released : September 2023
A19: Summary
A20: ELI 1.5 introduces slight modifications driven by modifications in the ELI-DL extension model.
A21: The most significant change is the addition of a couple of high-level properties eli:refers_to / eli:is_referred_to_by at the Work or Expression level. “refers_to” is meant to indicate a reference from the content of a work to any other entity, be it another work, or an agent or activity. As such, eli:refers_to is a super-property of eli:cites.
A22: Note that other kinds of links such as eli:changes, amends, etc. Have not been declared subproperties of eli:refers_to, as they are to be understood from a legal perspective, not necessarily involving that the changes/amended work is actually written as a reference in the text.
A23: Backward-compatibility
A24: ELI 1.5 is backward compatible with ELI 1.4.
A25: It is not required to change existing ELI metadata publication.
A26: Semantic changes
A27: • Introduced eli:refers_to / eli:is_referred_to_by on Work or Expression : “Any entity that this work or expression refers to ; typically references are made to other Works, but it can be also to legislative processes, persons, etc.”
A28: • Made eli:cites / eli:cited_by subproperties of eli:refers_to / eli:is_referred_to_by
... A33: None

Sheet ELI Implementation
A1: ELI Implementation
A3: Abbreviations
A4: URIs are cited in the text of this document in an abbreviated form:
A5: URI | B5: Abbrevisation | C5: What it stands for
A6: http://data.europa.eu/eli/ontology# | B6: eli: | C6: Europen Legislation Identifier (ELI)
A7: http://data.europa.eu/eli/eli-draft-legislation-ontology# | B7: eli-dl: | C7: ELI for draft legislation (ELI-DL)
A8: http://www.w3.org/1999/02/22-rdf-syntax-ns# | B8: rdf: | C8: Resource Description Framework (RDF)
A9: http://www.w3.org/2000/01/rdf-schema# | B9: rdfs:
A10: http://www.w3.org/2004/02/skos/core# | B10: skos: | C10: Simple Knolwedge Organiszation System (SKOS)
A11: http://purl.org/dc/terms/ | B11: dct: | C11: Dublin Core Terms Metadata (DCT)
A12: https://www.iana.org/assignments/media-types/ | B12: iana:
A14: So, for example, eli:LegalResource is an abbreviation of <http://data.europa.eu/eli/ontology#LegalResource>.
A17: ELI URI identifiers
A18: In the context of ELI, URIs are used to identify legal resources, their expressions in specific languages and formats, agents that passed or made the law, geographic areas, languages, and other concepts. Anything needed to express ELI metadata is identified by a URI. In the context of ELI, URI are said to be constructed using “com- ponents”; a URI component is a piece of information used as part the URI, like {year}, {type_document}, {language}, etc. Components are usually separated by “/”, e.g. http://exemple.eu/eli/{type_docu- ment}/{year}/{language}.
A20: Requirements
A21: close to citation; not opaque or obscure; readable by end users
A22: stable components over time
A23: hierarchical structure
A25: Terms | B25: Description | F25: Example
A26: URI | B26: Identification
A27: URL | B27: Location
A28: Canoncial URIs | B28: the official URI to identify a resource; typically this URI would be used as the subject of the RDF triples used to encode the data, and would be the one stored as the primary key in a metadata database, if such a database exists
A29: Alises URIs | B29: other URIs to refer to resources that are identified by a canonical URI. These aliases URIs can serve as alternative ways for users to identify or access the corresponding resource but are typically not used when expressing metadata internally | F29: http://legifrance.gouv.fr/eli/loi/2014/10/13/AGRX1324417L/jo/texte has the alias http://legifrance.gouv.fr/eli/loi/2014/10/13/2014-1170/jo/texte.
A30: Full URIs | B30: Full URIs serve as identifiers for legislation
A31: Incomplete URIs / Partial URIs | B31: link to the beginning of the URI | F31: /eli/{typedoc} should return a (paginated) list of all the documents of the given type. /eli/{typedoc}/{year} should return a (paginated) list of all the documents of the given type published in the given year. /eli/{typedoc}/{year}/{natural_number} should redirect to the latest consolidated version or base act of the document with the given document type, year, and number.
A32: ELI Registry (EUR-LEX) | B32: registry of the ELI identifier schemes used by the member states that have implemented ELI | F32: http://eur-lex.europa.eu/eli-register/about.html
A33: EU Office of Publications - Directive / Regulation | B33: Example URI | F33: http://data.europa.eu/eli/{typedoc}/{year}/ {natural_number}/oj: canonical ELI to identify a directive or regulation.
A34: EU Office of Publications - Directive / Regulation - Corrigendum | B34: Example URI | F34: http://data.europa.eu/eli/{typedoc}/{year}/ {natural_number}/corrigendum/{publication_ date}/oj: canonical ELI to identify a corrigendum.

Sheet ELI Ontology
A1: Source: https://op.europa.eu/en/web/eu-vocabularies/dataset/-/resource?uri=http://publications.europa.eu/resource/dataset/eli
A2: Documentation
A4: ELI ontology version 1.5 | C4: Blue cells indicate semantic changes from v1.4
C5: Light blue cells indicate editorial changes from v1.4
C6: Red cells indicate important cardinality characteristic (mandatory / not repeatable)
B7: Namespace : | C7: http://data.europa.eu/eli/ontology#
A9: Name | B9: Based on (superproperty, superclass, broader) | C9: Applicable to (domain) | D9: Allowed values (range) | E9: Mandatory | F9: Repeatable | G9: Description | H9: Created in | I9: Modified in | J9: History note
A10: Generic Classes
A11: Work | B11: frbroo:F1_Work | C11: n/a | D11: n/a | E11: n/a | F11: n/a | G11: Any distinct intellectual creation (i.e., the intellectual content), in the context of ELI. The substance of Work is ideas. | H11: 1.3 | I11: 1.3
A12: ComplexWork | B12: eli:Work | C12: n/a | D12: n/a | E12: n/a | F12: n/a | G12: Works that have other works as members. The members of a Complex Work may constitute alternatives to or derivatives of other members of the same Complex Work. Typically the members of the complex work represent the successive temporal versions of an act, while the complex work represents the act independantly of one of its version. | H12: 1.4 | I12: 1.4
A13: WorkSubdivision | B13: eli:Work | C13: n/a | D13: n/a | E13: n/a | F13: n/a | G13: A component of a work, at an arbitrary level of precision. A subdivision can be linked with its parent and children subdivision using eli:has_part / eli:is_part_of. | H13: 1.4 | I13: 1.4
A14: Expression | B14: frbroo:F22_Self-Contained_Expression | C14: n/a | D14: n/a | E14: n/a | F14: n/a | G14: The intellectual realisation of a Work in the form of identifiable immaterial objects, such as, but not limited to, text. The substance of Expression is signs. An Expression cannot exist without a physical carrier but do not depend on a specific physical carrier and can exist on one or more carriers simultaneously. | H14: 1.3 | I14: 1.3
A15: Manifestation | B15: frbroo:F3_Manifestation_Product_Type | C15: n/a | D15: n/a | E15: n/a | F15: n/a | G15: The physical embodiment of an Expression, either on paper or in any electronic format. The substance of Manifestation is not only signs, but also the manner in which they are presented to be consumed by users, including the kind of media adopted. | H15: 1.3 | I15: 1.4
A16: Agent | B16: frbroo:E39_Actor | C16: n/a | D16: n/a | E16: n/a | F16: n/a | G16: Individual people or groups of people, like an institution with a legal recognition, who have the potential to perform intentional actions for which they can be held responsible. | H16: 1.0 | I16: 1.4 | J16: V1.4 : subClassOf E39_ACtor instead of equivalent. V1.3 : added a definition.
A17: Person | B17: eli:Agent, frbroo:F10_Person | C17: n/a | D17: n/a | E17: n/a | F17: n/a | G17: A real person who live or has lived. | H17: 1.3 | I17: 1.4 | J17: v1.4 : set as subclass of F10_Person
A18: Organization | B18: eli:Agent, frbroo:F11_Corporate_Body | C18: n/a | D18: n/a | E18: n/a | F18: n/a | G18: Institutions or groups of people that have obtained a legal recognition as a group and can act collectively as agents. | H18: 1.3 | I18: 1.4 | J18: v1.4 : set as subclass of F11_Corporate_Body
A20: Legislation-specific classes
A21: LegalResource | B21: eli:Work | C21: n/a | D21: n/a | E21: n/a | F21: n/a | G21: A work in a legislative corpus. This applies to acts that have been legally enacted (whether or not they are still in force). For example, the abstract concept of the legal resource; e.g. "act 3 of 2005" (adapted from Akoma Ntoso) A legal resource can represent a legal act or any component of a legal act, like an article. Legal resources can be linked together using properties defined in the model. Note that ELI ontology accommodates different point of view on what should be considered a new legal resource, or a new legal expression of the same resource. Typically, a consolidated version can be viewed, in the context of ELI, either as separate legal resource (linked to original version and previous consolidated version using corresponding ELI relations), or as a different legal expression of the same legal resource. | H21: 1.0 | I21: 1.3 | J21: v1.3 : declared as a subclass of eli:Work v1.2 : replaced reference of RDA with FRBRoo (for more information on FRBRoo, see https://www.ifla.org/node/10171) .
A22: LegalResourceSubdivision | B22: eli:LegalResource + eli:WorkSubdivision | C22: n/a | D22: n/a | E22: n/a | F22: n/a | G22: A component of a legal act, at an arbitrary level of precision, like a chapter, an article, an alinea, a paragraph or an list item. A subdivision can be linked with its parent and children subdivision using eli:has_part / eli:is_part_of. | H22: 1.1 | I22: 1.4 | J22: v1.4 : added WorkSubdivision as a superclass
A23: LegalExpression | B23: eli:Expression | C23: n/a | D23: n/a | E23: n/a | F23: n/a | G23: The intellectual realisation of a legal resource in the form of a "sequence of signs" (typically alpha-numeric characters in a legal context). For example, any version of the legal resource whose content is specified and different from others for any reason: language, versions, etc.; Note that ELI ontology accommodates different point of view on what should be considered a new legal resource, or a new legal expression of the same resource. Typically, a consolidated version can be viewed, in the context of ELI, either as separate legal resource (linked to original version and previous consolidated version using corresponding ELI relations), or as a different legal expression of the same legal resource. | H23: 1.0 | I23: 1.3 | J23: v1.3 : declared as a subclass of eli:Expression v1.2 : replaced reference of RDA with FRBRoo (for more information on FRBRoo, see https://www.ifla.org/node/10171) .
A24: Format | B24: eli:Manifestation | C24: n/a | D24: n/a | E24: n/a | F24: n/a | G24: The physical embodiment of a legal expression, either on paper or in any electronic format. For example, any electronic or physical format of the legal expression (XML, TIFF, PDF, etc.) ; e.g. PDF version of act 3 of 2005. (adapted from Akoma Ntoso). Note that the notion of Format in ELI is more precise than a FRBR Manifestation in the sense that a Format in ELI can carry a legal value (see the property eli:legal_value). | H24: 1.0 | I24: 1.3 | J24: v1.3 : declared as a sublcass of eli:Manifestation v1.2 : replaced reference of RDA with FRBRoo (for more information on FRBRoo, see https://www.ifla.org/node/10171) .
A27: Properties : Generic FRBR structure
A28: is_part_of | B28: dcterms:isPartOf | C28: Work | D28: Work | E28: no | F28: yes | G28: Indicates a work in which this one is physically included. Covers the case of text included in an Official Journal, or an article included in a text. For the notion of conceptual/temporal inclusion, use eli:is_member_of. | H28: 1.0 | I28: 1.3 | J28: v1.3 : broaden the domain and range to Work instead of LegalResource Starting with v1.1, the notion of conceptual inclusion is expressed with eli:is_member_of instead of eli:is_part_of.
A29: has_part | B29: dcterms:hasPart | C29: Work | D29: Work | E29: no | F29: yes | G29: Inverse of "is_part_of" | H29: 1.0 | I29: 1.3 | J29: v1.3 : broaden the domain and range to Work instead of LegalResource
A30: is_member_of | B30: dcterms:isPartOf frbroo:R10i_is_member_of | C30: Work | D30: Work | E30: no | F30: yes | G30: Indicates that this work is conceptually included in another one. In the case of a legislation, its successive temporal versions are conceptually members of a single « abstract » resource. For the notion of physical inclusion, use eli:is_part_of. | H30: 1.1 | I30: 1.3 | J30: v1.3 : broaden the domain and range to Work instead of LegalResource v1.2 : replaced reference of RDA with FRBRoo.
A31: has_member | B31: dcterms:hasPart frbroo:R10_has_member | C31: Work | D31: Work | E31: no | F31: yes | G31: Indicates that this work conceptually includes another one. For the notion of physical inclusion, use eli:has_part. | H31: 1.1 | I31: 1.3 | J31: v1.3 : broaden the domain and range to Work instead of LegalResource v1.2 : replaced reference of RDA with FRBRoo.
A32: is_realized_by | B32: frbroo:R3_is_realised_in | C32: Work | D32: Expression | E32: no | F32: yes | G32: Relates a work to an expression of this work in the form of a "sequence of signs" (typically alpha-numeric characters in a legal context). Inverse of "realizes". | H32: 1.0 | I32: 1.3 | J32: v1.3 : broaden the domain to Work instead of LegalResource and range to Expression instead of LegalExpression. v1.2 : replaced reference of RDA with FRBRoo.
A33: realizes | B33: frbroo:R3i_realises | C33: Expression | D33: Work | E33: yes | F33: no | G33: Relates an expression to a work realised through that expression. Inverse of "is_realized_by". | H33: 1.0 | I33: 1.3 | J33: v1.3 : broaden the domain to Expression instead of LegalExpression and the range to Work instead of LegalResource. v1.2 : replaced reference of RDA with FRBRoo.
A34: is_embodied_by | B34: frbroo:R4_carriers_provided_by | C34: Expression | D34: Manifestation | E34: no | F34: yes | G34: Relates an expression to a manifestation of that expression. Inverse of "embodies". | H34: 1.0 | I34: 1.3 | J34: v1.3 : broaden the domain to Expression instead of LegalExpression and the range to Manifestation instead of Format. v1.2 : replaced reference of RDA with FRBRoo.
A35: embodies | B35: frbroo:R4i_comprises_carriers_of | C35: Manifestation | D35: Expression | E35: yes | F35: no | G35: Relates a manifestation to the expression that it embodies. Inverse of "is_embodied_by". | H35: 1.0 | I35: 1.3 | J35: v1.3 : broaden the domain to Manifestation instead of Format and the range to Expression instead of LegalExpression. v1.2 : replaced reference of RDA with FRBRoo. In v1.1, this was declared functional (the constraint was missing in 1.0)
A36: is_exemplified_by | B36: frbroo:R7i_has_example | C36: Manifestation | D36: owl:Thing | E36: no | F36: yes | G36: Link to a concrete file URL. Relates a manifestation to a single exemplar or instance of that manifestation. | H36: 1.0 | I36: 1.3 | J36: v1.3 : broaden the domain to Manifestation instead of Format. v1.2 : replaced reference of RDA with FRBRoo.
A39: Properties : description
A40: number | C40: Work; Expression | D40: xsd:string | E40: no | F40: yes | G40: An identifier or other disambiguating feature for a work or expression. This can be the number of a legislation, the number of an article, or the issue number of an official journal. | H40: 1.1 | I40: 1.5 | J40: v1.5 : broaden the domain to Work or Expression instead of LegalResource or LegalExpression.
A41: uri_schema | C41: LegalResource; LegalExpression; Format | D41: owl:Thing | E41: no | F41: yes | G41: Schema describing the URI of an ELI instance. ELI uses URI template specifications (IETF RFC 6570). Schemes should be associated with member states and will be published in a registry. | H41: 1.0
A42: id_local | B42: dcterms:identifier | C42: LegalResource; LegalExpression; Format | D42: xsd:String or xsd:AnyURI | E42: no | F42: yes | G42: The unique identifier used in a local reference system to maintain backwards compatibility. For examples the CELEX at EU level, or the NOR in France | H42: 1.0
A43: work_type | B43: dcterms:type | C43: Work | D43: WorkType, corresponding to a local concept scheme. | E43: no | F43: yes | G43: The type of a work, taken from a controlled vocabulary. Member States need to define their own work type values. | H43: 1.4
A44: type_document | B44: work_type | C44: LegalResource | D44: eli:ResourceType, corresponding to a local concept scheme. | E44: yes | F44: yes | G44: The type of a legal resource (e.g. "Directive", "Règlement grand ducal", "law", "règlement ministériel", "draft proposition", "Parliamentary act", etc.). Member states are encouraged to make their own list of values in the corresponding concept scheme. EU Publications Office provides a list of values for EU resource types at https://op.europa.eu/en/web/eu-vocabularies/at-dataset/-/resource/dataset/resource-type | H44: 1.0 | I44: 1.4 | J44: v1.4 : Moved under work_type v1.3 : Updated link to EU vocabularies website in the definition.
A45: type_subdivision | B45: dcterms:type | C45: WorkSubdivision | D45: eli:SubdivisionType, corresponding to a local concept scheme | E45: no | F45: no | G45: The type of a document subdivision (e.g. "Article", "Paragraph", "Section", etc.). A subdivision can have only one type. ELI does not specify a list of possible values. Member states are encouraged to make their own list of values in the corresponding concept scheme. EU Publication Office provies a list of values for EU resource types at https://op.europa.eu/en/web/eu-vocabularies/at-dataset/-/resource/dataset/subdivision | H45: 1.3 | I45: 1.4 | J45: v1.4 : Broaden range to WorkSubdivision
A46: relevant_for | B46: dcterms:coverage | C46: LegalResource; LegalExpression | D46: eli:AdministrativeArea, containing the list of administrative territorial units defined in http://publications.europa.eu/mdr/authority/atu | E46: no | F46: yes | G46: Refers to a place or an area associated with the resource. This covers the notions of jurisdiction, sovereignty, applicability or administrative area. The place identifier can be taken from the Administrative Territorial Unit table published of the EU Publications Office at https://op.europa.eu/en/web/eu-vocabularies/at-dataset/-/resource/dataset/atu. Member States don't have to recreate their own list of values. The group notes the limitations of what can be said with a single property; member states can refine this notion by declaring specific sub properties. | H46: 1.0 | I46: 1.3 | J46: v1.3 : Updated link to EU vocabularies website in the definition. Starting from v1.1, the values for this property can be taken from the named authority list published by the Office of Publications instead of defining new values.
A47: jurisdiction | B47: eli:relevant_for | C47: LegalResource; LegalExpression | D47: eli:AdministrativeArea, containing the list of administrative territorial units defined in http://publications.europa.eu/mdr/authority/atu | E47: no | F47: yes | G47: The jurisdiction from which the legal resource originates. The place identifier can be taken from the Administrative Territorial Unit table published of the EU Publications Office at https://op.europa.eu/en/web/eu-vocabularies/at-dataset/-/resource/dataset/atu. Member States don't have to recreate their own list of values. | H47: 1.1 | I47: 1.3 | J47: v1.3 : Updated link to EU vocabularies website in the definition.
...

Sheet ELI Diagrams
A1: Source: https://op.europa.eu/en/web/eu-vocabularies/dataset/-/resource?uri=http://publications.europa.eu/resource/dataset/eli
A2: Documentation

Sheet ELI Property Ranges (SHACL)
A1: Source; Validation Rules
A3: Graph URI | B3: http://data.europa.eu/eli/shapes
A11: The URI of the constraint | B11: The predicate on which the constraint applies, when there is only one. | C11: The Shape to which the constraint is attached. | D11: The severity of the constraint | E11: The name of the constraint | F11: The textual description of the constraint | G11: The type of node that the values should have (sh:IRI or sh:Literal) | J11: The expected class of the values of this property (when there is only one) (striketrough cells are ignored) | K11: For literal values, the expected datatypes of the values | L11: The fixed list of expected values for the property, when the number of possible values is small and known in advance. | M11: The beginning of the URI pattern that the property values should have.
A12: URI | B12: path - informative - not converted | C12: shape - informative - not converted | D12: sh:severity | E12: sh:name@en | F12: sh:description^^xsd:string | G12: sh:nodeKind | H12: sh:minCount^^xsd:integer | I12: sh:maxCount^^xsd:integer | J12: sh:class(separator="," wrapper="sh:or") | K12: sh:datatype | L12: sh:in | M12: sh:pattern^^xsd:string
A15: eli:Work
A16: elish:Work_is_part_of | B16: eli:is_part_of | C16: eli:Work | J16: eli:Work
A17: elish:Work_has_part | B17: eli:has_part | C17: eli:Work | J17: eli:Work
A18: elish:Work_is_member_of | B18: eli:is_member_of | C18: eli:Work | J18: eli:Work
A19: elish:Work_has_member | B19: eli:has_member | C19: eli:Work | J19: eli:Work
A20: elish:Work_is_realized_by | B20: eli:is_realized_by | C20: eli:Work | J20: eli:Expression
A21: elish:Work_work_type | B21: eli:work_type | C21: eli:Work
A24: elish:LegalResource_based_on | B24: eli:based_on | C24: eli:Work | J24: eli:Work, eli:Expression
A25: eli:Expression
A26: elish:Expression_realizes | B26: eli:realizes | C26: eli:Expression | J26: eli:Work
A27: elish:Expression_is_embodied_by | B27: eli:is_embodied_by | C27: eli:Expression | J27: eli:Format
A31: eli:Work or eli:Expression
A34: =IFERROR(__xludf.DUMMYFUNCTION("CONCATENATE(""elish:"",REGEXREPLACE(C32,""eli:|[, ]"",""""),""_"",REGEXREPLACE(B32,""eli:"",""""))"),"elish:WorkExpression_is_derivative_of") -> elish:WorkExpression_is_derivative_of | B34: eli:is_derivative_of | C34: eli:Work, eli:Expression | J34: eli:Work, eli:Expression
A35: =IFERROR(__xludf.DUMMYFUNCTION("CONCATENATE(""elish:"",REGEXREPLACE(C33,""eli:|[, ]"",""""),""_"",REGEXREPLACE(B33,""eli:"",""""))"),"elish:WorkExpression_has_derivative") -> elish:WorkExpression_has_derivative | B35: eli:has_derivative | C35: eli:Work, eli:Expression | J35: eli:Work, eli:Expression
A36: =IFERROR(__xludf.DUMMYFUNCTION("CONCATENATE(""elish:"",REGEXREPLACE(C34,""eli:|[, ]"",""""),""_"",REGEXREPLACE(B34,""eli:"",""""))"),"elish:WorkExpression_has_annex") -> elish:WorkExpression_has_annex | B36: eli:has_annex | C36: eli:Work, eli:Expression | J36: eli:Work, eli:Expression
A37: =IFERROR(__xludf.DUMMYFUNCTION("CONCATENATE(""elish:"",REGEXREPLACE(C35,""eli:|[, ]"",""""),""_"",REGEXREPLACE(B35,""eli:"",""""))"),"elish:WorkExpression_is_annex_of") -> elish:WorkExpression_is_annex_of | B37: eli:is_annex_of | C37: eli:Work, eli:Expression | J37: eli:Work, eli:Expression
A38: =IFERROR(__xludf.DUMMYFUNCTION("CONCATENATE(""elish:"",REGEXREPLACE(C36,""eli:|[, ]"",""""),""_"",REGEXREPLACE(B36,""eli:"",""""))"),"elish:WorkExpression_changes") -> elish:WorkExpression_changes | B38: eli:changes | C38: eli:Work, eli:Expression | J38: eli:Work, eli:Expression
A39: =IFERROR(__xludf.DUMMYFUNCTION("CONCATENATE(""elish:"",REGEXREPLACE(C37,""eli:|[, ]"",""""),""_"",REGEXREPLACE(B37,""eli:"",""""))"),"elish:WorkExpression_changed_by") -> elish:WorkExpression_changed_by | B39: eli:changed_by | C39: eli:Work, eli:Expression | J39: eli:Work, eli:Expression
A40: =IFERROR(__xludf.DUMMYFUNCTION("CONCATENATE(""elish:"",REGEXREPLACE(C38,""eli:|[, ]"",""""),""_"",REGEXREPLACE(B38,""eli:"",""""))"),"elish:WorkExpression_basis_for") -> elish:WorkExpression_basis_for | B40: eli:basis_for | C40: eli:Work, eli:Expression | J40: eli:Work
A41: =IFERROR(__xludf.DUMMYFUNCTION("CONCATENATE(""elish:"",REGEXREPLACE(C39,""eli:|[, ]"",""""),""_"",REGEXREPLACE(B39,""eli:"",""""))"),"elish:WorkExpression_corrects") -> elish:WorkExpression_corrects | B41: eli:corrects | C41: eli:Work, eli:Expression | J41: eli:Work, eli:Expression
A42: =IFERROR(__xludf.DUMMYFUNCTION("CONCATENATE(""elish:"",REGEXREPLACE(C40,""eli:|[, ]"",""""),""_"",REGEXREPLACE(B40,""eli:"",""""))"),"elish:WorkExpression_corrected_by") -> elish:WorkExpression_corrected_by | B42: eli:corrected_by | C42: eli:Work, eli:Expression | J42: eli:Work, eli:Expression
A43: =IFERROR(__xludf.DUMMYFUNCTION("CONCATENATE(""elish:"",REGEXREPLACE(C41,""eli:|[, ]"",""""),""_"",REGEXREPLACE(B41,""eli:"",""""))"),"elish:WorkExpression_amends") -> elish:WorkExpression_amends | B43: eli:amends | C43: eli:Work, eli:Expression | J43: eli:Work, eli:Expression
A44: =IFERROR(__xludf.DUMMYFUNCTION("CONCATENATE(""elish:"",REGEXREPLACE(C42,""eli:|[, ]"",""""),""_"",REGEXREPLACE(B42,""eli:"",""""))"),"elish:WorkExpression_amended_by") -> elish:WorkExpression_amended_by | B44: eli:amended_by | C44: eli:Work, eli:Expression | J44: eli:Work, eli:Expression
A45: eli:Manifestation
A46: elish:Manifestation_embodies | B46: eli:embodies | C46: eli:Manifestation | J46: eli:Expression
A50: eli:LegalResource or eli:LegalExpression or eli:Format
A53: eli:LegalResource or eli:LegalExpression
A67: elish:LegalResourceLegalExpression_consolidates | B67: eli:consolidates | C67: eli:LegalResource, eli:LegalExpression | J67: eli:LegalResource, eli:LegalExpression
A68: elish:LegalResourceLegalExpression_consolidated_by | B68: eli:consolidated_by | C68: eli:LegalResource, eli:LegalExpression | J68: eli:LegalResource, eli:LegalExpression
A72: elish:LegalResourceLegalExpression_commences | B72: eli:commences | C72: eli:LegalResource, eli:LegalExpression | J72: eli:LegalResource, eli:LegalExpression
A73: elish:LegalResourceLegalExpression_commenced_by | B73: eli:commenced_by | C73: eli:LegalResource, eli:LegalExpression | J73: eli:LegalResource, eli:LegalExpression
A74: elish:LegalResourceLegalExpression_repeals | B74: eli:repeals | C74: eli:LegalResource, eli:LegalExpression | J74: eli:LegalResource, eli:LegalExpression
A75: elish:LegalResourceLegalExpression_repealed_by | B75: eli:repealed_by | C75: eli:LegalResource, eli:LegalExpression | J75: eli:LegalResource, eli:LegalExpression
A80: elish:LegalResourceLegalExpression_cited_by_case_law | B80: eli:cited_by_case_law | C80: eli:LegalResource, eli:LegalExpression
A81: elish:LegalResourceLegalExpression_cited_by_case_law_reference | B81: eli:cited_by_case_law_reference | C81: eli:LegalResource, eli:LegalExpression
A82: eli:LegalResource
...

Sheet ELI-DL Property Core (SHACL)
A1: Source; Validation Rules
A3: Graph URI | B3: http://data.europa.eu/eli/shapes
A11: The URI of the constraint | B11: The predicate on which the constraint applies, when there is only one. | C11: The Shape to which the constraint is attached. | D11: The severity of the constraint | E11: The name of the constraint | F11: The textual description of the constraint | G11: The type of node that the values should have (sh:IRI or sh:Literal) | J11: The expected class of the values of this property (when there is only one) (striketrough cells are ignored) | K11: For literal values, the expected datatypes of the values | L11: The fixed list of expected values for the property, when the number of possible values is small and known in advance. | M11: The beginning of the URI pattern that the property values should have.
A12: URI | B12: sh:path | C12: ^sh:property(separator=",") | D12: sh:severity | E12: sh:name@en | F12: sh:description^^xsd:string | G12: sh:nodeKind | H12: sh:minCount^^xsd:integer | I12: sh:maxCount^^xsd:integer | J12: sh:class(separator="," wrapper="sh:or") | K12: sh:datatype | L12: sh:in | M12: sh:pattern^^xsd:string
A15: eli:Work
A16: =IFERROR(__xludf.DUMMYFUNCTION("CONCATENATE(""elish:"",REGEXREPLACE(C14,""eli:|[, ]"",""""),""_"",REGEXREPLACE(B14,""eli:"",""""))"),"elish:Work_is_part_of") -> elish:Work_is_part_of | B16: eli:is_part_of | C16: eli:Work | D16: sh:Violation | E16: is part of | F16: eli:is_part_of MUST have an IRI value | G16: sh:IRI | J16: eli:Work
A17: =IFERROR(__xludf.DUMMYFUNCTION("CONCATENATE(""elish:"",REGEXREPLACE(C15,""eli:|[, ]"",""""),""_"",REGEXREPLACE(B15,""eli:"",""""))"),"elish:Work_has_part") -> elish:Work_has_part | B17: eli:has_part | C17: eli:Work | D17: sh:Violation | E17: has part | F17: eli:has_part MUST have an IRI value | G17: sh:IRI | J17: eli:Work
A18: =IFERROR(__xludf.DUMMYFUNCTION("CONCATENATE(""elish:"",REGEXREPLACE(C16,""eli:|[, ]"",""""),""_"",REGEXREPLACE(B16,""eli:"",""""))"),"elish:Work_is_member_of") -> elish:Work_is_member_of | B18: eli:is_member_of | C18: eli:Work | D18: sh:Violation | E18: is member of | F18: eli:is_member_of MUST have an IRI value | G18: sh:IRI | J18: eli:Work
A19: =IFERROR(__xludf.DUMMYFUNCTION("CONCATENATE(""elish:"",REGEXREPLACE(C17,""eli:|[, ]"",""""),""_"",REGEXREPLACE(B17,""eli:"",""""))"),"elish:Work_has_member") -> elish:Work_has_member | B19: eli:has_member | C19: eli:Work | D19: sh:Violation | E19: has member | F19: eli:has_member MUST have an IRI value | G19: sh:IRI | J19: eli:Work
A20: =IFERROR(__xludf.DUMMYFUNCTION("CONCATENATE(""elish:"",REGEXREPLACE(C18,""eli:|[, ]"",""""),""_"",REGEXREPLACE(B18,""eli:"",""""))"),"elish:Work_is_realized_by") -> elish:Work_is_realized_by | B20: eli:is_realized_by | C20: eli:Work | D20: sh:Violation | E20: is realized by | F20: eli:is_realized_by MUST have an IRI value | G20: sh:IRI | J20: eli:Expression
A21: =IFERROR(__xludf.DUMMYFUNCTION("CONCATENATE(""elish:"",REGEXREPLACE(C19,""eli:|[, ]"",""""),""_"",REGEXREPLACE(B19,""eli:"",""""))"),"elish:Work_work_type") -> elish:Work_work_type | B21: eli:work_type | C21: eli:Work | D21: sh:Violation | E21: work_type | F21: eli:work_type MUST have an IRI value | G21: sh:IRI
A22: =IFERROR(__xludf.DUMMYFUNCTION("CONCATENATE(""elish:"",REGEXREPLACE(C20,""eli:|[, ]"",""""),""_"",REGEXREPLACE(B20,""eli:"",""""))"),"elish:Work_is_about") -> elish:Work_is_about | B22: eli:is_about | C22: eli:Work | D22: sh:Violation | E22: is about | F22: eli:is_about MUST be an IRI | G22: sh:IRI
A23: =IFERROR(__xludf.DUMMYFUNCTION("CONCATENATE(""elish:"",REGEXREPLACE(C21,""eli:|[, ]"",""""),""_"",REGEXREPLACE(B21,""eli:"",""""))"),"elish:Work_date_document") -> elish:Work_date_document | B23: eli:date_document | C23: eli:Work | D23: sh:Violation | E23: date document | F23: A Work MUST not have more than one date_document. eli:date_document MUST have a literal value with datatype xsd:date | G23: sh:Literal | I23: 1 | K23: xsd:date
A24: =IFERROR(__xludf.DUMMYFUNCTION("CONCATENATE(""elish:"",REGEXREPLACE(C22,""eli:|[, ]"",""""),""_"",REGEXREPLACE(B22,""eli:"",""""))"),"elish:Work_based_on") -> elish:Work_based_on | B24: eli:based_on | C24: eli:Work | D24: sh:Violation | E24: based on | F24: eli:based_on MUST have an IRI value | G24: sh:IRI | J24: eli:Work, eli:Expression
A25: eli:Expression
A26: =IFERROR(__xludf.DUMMYFUNCTION("CONCATENATE(""elish:"",REGEXREPLACE(C24,""eli:|[, ]"",""""),""_"",REGEXREPLACE(B24,""eli:"",""""))"),"elish:Expression_realizes") -> elish:Expression_realizes | B26: eli:realizes | C26: eli:Expression | D26: sh:Violation | E26: realizes | F26: eli:realizes MUST be an IRI | G26: sh:IRI | J26: eli:Work
A27: =IFERROR(__xludf.DUMMYFUNCTION("CONCATENATE(""elish:"",REGEXREPLACE(C25,""eli:|[, ]"",""""),""_"",REGEXREPLACE(B25,""eli:"",""""))"),"elish:Expression_is_embodied_by") -> elish:Expression_is_embodied_by | B27: eli:is_embodied_by | C27: eli:Expression | D27: sh:Violation | E27: is embodied by | F27: eli:is_embodied_by MUST be an IRI | G27: sh:IRI | J27: eli:Format
A28: =IFERROR(__xludf.DUMMYFUNCTION("CONCATENATE(""elish:"",REGEXREPLACE(C26,""eli:|[, ]"",""""),""_"",REGEXREPLACE(B26,""eli:"",""""))"),"elish:Expression_title") -> elish:Expression_title | B28: eli:title | C28: eli:Expression | D28: sh:Violation | E28: title | F28: eli:title MUST have a literal value | G28: sh:Literal
A29: =IFERROR(__xludf.DUMMYFUNCTION("CONCATENATE(""elish:"",REGEXREPLACE(C27,""eli:|[, ]"",""""),""_"",REGEXREPLACE(B27,""eli:"",""""))"),"elish:Expression_title_short") -> elish:Expression_title_short | B29: eli:title_short | C29: eli:Expression | D29: sh:Violation | E29: title short | F29: eli:title_short MUST have a literal value | G29: sh:Literal
A30: =IFERROR(__xludf.DUMMYFUNCTION("CONCATENATE(""elish:"",REGEXREPLACE(C28,""eli:|[, ]"",""""),""_"",REGEXREPLACE(B28,""eli:"",""""))"),"elish:Expression_title_alternative") -> elish:Expression_title_alternative | B30: eli:title_alternative | C30: eli:Expression | D30: sh:Violation | E30: title alternative | F30: eli:title_alternative MUST have a literal value | G30: sh:Literal
A31: eli:Work or eli:Expression
A32: =IFERROR(__xludf.DUMMYFUNCTION("CONCATENATE(""elish:"",REGEXREPLACE(C30,""eli:|[, ]"",""""),""_"",REGEXREPLACE(B30,""eli:"",""""))"),"elish:WorkExpression_number") -> elish:WorkExpression_number | B32: eli:number | C32: eli:Work, eli:Expression | D32: sh:Violation | E32: number | F32: eli:number MUST have a literal value with datatype xsd:string | G32: sh:Literal | K32: xsd:string
A33: =IFERROR(__xludf.DUMMYFUNCTION("CONCATENATE(""elish:"",REGEXREPLACE(C31,""eli:|[, ]"",""""),""_"",REGEXREPLACE(B31,""eli:"",""""))"),"elish:WorkExpression_refers_to") -> elish:WorkExpression_refers_to | B33: eli:refers_to | C33: eli:Work, eli:Expression | D33: sh:Violation | E33: refers_to | F33: eli:refers_to MUST have an IRI value | G33: sh:IRI
A34: elish:WorkExpression_inverse_is_referred_to_by | B34: ^eli:is_referred_to_by | C34: eli:Work, eli:Expression | D34: sh:Violation | E34: is_referred_to_by (inverse) | G34: sh:IRI
A35: =IFERROR(__xludf.DUMMYFUNCTION("CONCATENATE(""elish:"",REGEXREPLACE(C33,""eli:|[, ]"",""""),""_"",REGEXREPLACE(B33,""eli:"",""""))"),"elish:WorkExpression_is_derivative_of") -> elish:WorkExpression_is_derivative_of | B35: eli:is_derivative_of | C35: eli:Work, eli:Expression | D35: sh:Violation | E35: is_derivative_of | F35: eli:is_derivative_of MUST have an IRI value | G35: sh:IRI | J35: eli:Work, eli:Expression
A36: =IFERROR(__xludf.DUMMYFUNCTION("CONCATENATE(""elish:"",REGEXREPLACE(C34,""eli:|[, ]"",""""),""_"",REGEXREPLACE(B34,""eli:"",""""))"),"elish:WorkExpression_has_derivative") -> elish:WorkExpression_has_derivative | B36: eli:has_derivative | C36: eli:Work, eli:Expression | D36: sh:Violation | E36: has_derivative | F36: eli:has_derivative MUST have an IRI value | G36: sh:IRI | J36: eli:Work, eli:Expression
A37: =IFERROR(__xludf.DUMMYFUNCTION("CONCATENATE(""elish:"",REGEXREPLACE(C35,""eli:|[, ]"",""""),""_"",REGEXREPLACE(B35,""eli:"",""""))"),"elish:WorkExpression_has_annex") -> elish:WorkExpression_has_annex | B37: eli:has_annex | C37: eli:Work, eli:Expression | D37: sh:Violation | E37: has_annex | F37: eli:has_annex MUST have an IRI value | G37: sh:IRI | J37: eli:Work, eli:Expression
A38: =IFERROR(__xludf.DUMMYFUNCTION("CONCATENATE(""elish:"",REGEXREPLACE(C36,""eli:|[, ]"",""""),""_"",REGEXREPLACE(B36,""eli:"",""""))"),"elish:WorkExpression_is_annex_of") -> elish:WorkExpression_is_annex_of | B38: eli:is_annex_of | C38: eli:Work, eli:Expression | D38: sh:Violation | E38: is_annex_of | F38: eli:is_annex_of MUST have an IRI value | G38: sh:IRI | J38: eli:Work, eli:Expression
A39: =IFERROR(__xludf.DUMMYFUNCTION("CONCATENATE(""elish:"",REGEXREPLACE(C37,""eli:|[, ]"",""""),""_"",REGEXREPLACE(B37,""eli:"",""""))"),"elish:WorkExpression_changes") -> elish:WorkExpression_changes | B39: eli:changes | C39: eli:Work, eli:Expression | D39: sh:Violation | E39: changes | F39: eli:changes MUST have an IRI value | G39: sh:IRI | J39: eli:Work, eli:Expression
A40: =IFERROR(__xludf.DUMMYFUNCTION("CONCATENATE(""elish:"",REGEXREPLACE(C38,""eli:|[, ]"",""""),""_"",REGEXREPLACE(B38,""eli:"",""""))"),"elish:WorkExpression_changed_by") -> elish:WorkExpression_changed_by | B40: eli:changed_by | C40: eli:Work, eli:Expression | D40: sh:Violation | E40: changed by | F40: eli:changed_by MUST have an IRI value | G40: sh:IRI | J40: eli:Work, eli:Expression
A41: =IFERROR(__xludf.DUMMYFUNCTION("CONCATENATE(""elish:"",REGEXREPLACE(C39,""eli:|[, ]"",""""),""_"",REGEXREPLACE(B39,""eli:"",""""))"),"elish:WorkExpression_basis_for") -> elish:WorkExpression_basis_for | B41: eli:basis_for | C41: eli:Work, eli:Expression | D41: sh:Violation | E41: basis for | F41: eli:basis_for MUST have an IRI value | G41: sh:IRI | J41: eli:Work, eli:Expression
A42: =IFERROR(__xludf.DUMMYFUNCTION("CONCATENATE(""elish:"",REGEXREPLACE(C40,""eli:|[, ]"",""""),""_"",REGEXREPLACE(B40,""eli:"",""""))"),"elish:WorkExpression_corrects") -> elish:WorkExpression_corrects | B42: eli:corrects | C42: eli:Work, eli:Expression | D42: sh:Violation | E42: corrects | F42: eli:corrects MUST have an IRI value | G42: sh:IRI | J42: eli:Work, eli:Expression
A43: =IFERROR(__xludf.DUMMYFUNCTION("CONCATENATE(""elish:"",REGEXREPLACE(C41,""eli:|[, ]"",""""),""_"",REGEXREPLACE(B41,""eli:"",""""))"),"elish:WorkExpression_corrected_by") -> elish:WorkExpression_corrected_by | B43: eli:corrected_by | C43: eli:Work, eli:Expression | D43: sh:Violation | E43: corrected by | F43: eli:corrected_by MUST have an IRI value | G43: sh:IRI | J43: eli:Work, eli:Expression
A44: =IFERROR(__xludf.DUMMYFUNCTION("CONCATENATE(""elish:"",REGEXREPLACE(C42,""eli:|[, ]"",""""),""_"",REGEXREPLACE(B42,""eli:"",""""))"),"elish:WorkExpression_amends") -> elish:WorkExpression_amends | B44: eli:amends | C44: eli:Work, eli:Expression | D44: sh:Violation | E44: amends | F44: eli:amends MUST have an IRI value | G44: sh:IRI | J44: eli:Work, eli:Expression
A45: =IFERROR(__xludf.DUMMYFUNCTION("CONCATENATE(""elish:"",REGEXREPLACE(C43,""eli:|[, ]"",""""),""_"",REGEXREPLACE(B43,""eli:"",""""))"),"elish:WorkExpression_amended_by") -> elish:WorkExpression_amended_by | B45: eli:amended_by | C45: eli:Work, eli:Expression | D45: sh:Violation | E45: amended by | F45: eli:amended_by MUST have an IRI value | G45: sh:IRI | J45: eli:Work, eli:Expression
A46: eli:Manifestation
A47: =IFERROR(__xludf.DUMMYFUNCTION("CONCATENATE(""elish:"",REGEXREPLACE(C45,""eli:|[, ]"",""""),""_"",REGEXREPLACE(B45,""eli:"",""""))"),"elish:Manifestation_embodies") -> elish:Manifestation_embodies | B47: eli:embodies | C47: eli:Manifestation | D47: sh:Violation | E47: embodies | F47: eli:embodies MUST have an IRI value | G47: sh:IRI | J47: eli:Expression
A48: =IFERROR(__xludf.DUMMYFUNCTION("CONCATENATE(""elish:"",REGEXREPLACE(C46,""eli:|[, ]"",""""),""_"",REGEXREPLACE(B46,""eli:"",""""))"),"elish:Manifestation_is_exemplified_by") -> elish:Manifestation_is_exemplified_by | B48: eli:is_exemplified_by | C48: eli:Manifestation | D48: sh:Violation | E48: is exemplified by | F48: eli:is_exemplified_by MUST have an IRI value | G48: sh:IRI
A49: =IFERROR(__xludf.DUMMYFUNCTION("CONCATENATE(""elish:"",REGEXREPLACE(C47,""eli:|[, ]"",""""),""_"",REGEXREPLACE(B47,""eli:"",""""))"),"elish:Manifestation_format") -> elish:Manifestation_format | B49: eli:format | C49: eli:Manifestation | D49: sh:Violation | E49: format | F49: eli:format MUST have an IRI value | G49: sh:IRI
A50: =IFERROR(__xludf.DUMMYFUNCTION("CONCATENATE(""elish:"",REGEXREPLACE(C48,""eli:|[, ]"",""""),""_"",REGEXREPLACE(B48,""eli:"",""""))"),"elish:Manifestation_media_type") -> elish:Manifestation_media_type | B50: eli:media_type | C50: eli:Manifestation | D50: sh:Violation | E50: media type | F50: eli:media_type MUST have an IRI value starting with "^http://www.iana.org/assignments/media-types/(.*)" | G50: sh:IRI | M50: "^https://www.iana.org/assignments/media-types/(.*)"
...

Sheet Schema.org Legislation (Mapping
A1: Source: https://op.europa.eu/en/web/eu-vocabularies/dataset/-/resource?uri=http://publications.europa.eu/resource/dataset/eli
A2: Documentation
A4: Mapping of ELI 1.5 with schema.org
C5: Yellow cells indicate classes or properties that are part of the legal extension of SDO (http://pending.schema.org/Legislation)
A7: Name
A8: Classes | C8: Schema.org mapping
A9: Work | B9: rdfs:subClassOf | C9: schema:CreativeWork
A10: ComplexWork | B10: rdfs:subClassOf | C10: schema:CreativeWork
A11: WorkSubdivision | B11: rdfs:subClassOf | C11: schema:CreativeWork
A12: Expression | B12: rdfs:subClassOf | C12: schema:CreativeWork
A13: Manifestation | B13: rdfs:subClassOf | C13: schema:MediaObject
A14: LegalResource | B14: rdfs:subClassOf | C14: schema:Legislation
A15: LegalResourceSubdivision | B15: rdfs:subClassOf | C15: schema:Legislation
A16: LegalExpression | B16: rdfs:subClassOf | C16: schema:Legislation
A17: Format | B17: rdfs:subClassOf | C17: schema:LegislationObject
A18: Agent | C18: - | D18: no equivalent mapping for this abstract class, but subclasses Person and Organization can be mapped to equivalent classes.
A19: Person | B19: owl:equivalentClass | C19: schema:Person
A20: Organization | B20: owl:equivalentClass | C20: schema:Organization
A22: Properties : FRBR structure | C22: Schema.org mapping
A23: is_part_of | B23: rdfs:subPropertyOf | C23: schema:isPartOf
A24: has_part | B24: rdfs:subPropertyOf | C24: schema:hasPart
A25: is_member_of | B25: rdfs:subPropertyOf | C25: schema:exampleOfWork
A26: has_member | B26: rdfs:subPropertyOf | C26: schema:workExample
A27: is_realized_by | B27: rdfs:subPropertyOf | C27: schema:workExample
A28: realizes | B28: rdfs:subPropertyOf | C28: schema:exampleOfWork
A29: is_embodied_by | B29: rdfs:subPropertyOf | C29: schema:encoding
A30: embodies | B30: rdfs:subPropertyOf | C30: schema:encodesCreativeWork
A31: is_exemplified_by | B31: rdfs:subPropertyOf | C31: schema:contentUrl
A32: Properties : description | C32: Schema.org mapping
A33: number | B33: rdfs:subPropertyOf | C33: schema:legislationIdentifier
A34: uri_schema | C34: - | D34: Not to be mapped to schema.org
A35: id_local | B35: rdfs:subPropertyOf | C35: schema:legislationIdentifier
A36: work_type | B36: owl:equivalentProperty | C36: schema:genre
A37: type_document | B37: owl:equivalentProperty | C37: schema:legislationType
A38: type_subdivision | B38: owl:equivalentProperty | C38: schema:legislationType
A39: relevant_for | B39: rdfs:subPropertyOf | C39: schema:spatialCoverage
A40: jurisdiction | B40: rdfs:subPropertyOf | C40: schema:spatialCoverage
A41: passed_by | B41: owl:equivalentProperty | C41: schema:legislationPassedBy
A42: countersigned_by | C42: - | D42: No equivalent property in current schema.org Legislation extension.
A43: responsibility_of | B43: rdfs:subPropertyOf | C43: schema:legislationResponsible
...

Sheet Schema.org PublicationIssue
B1: Mapping: Schema.org Publication > eCH-0296 (optional)
B2: Thing > CreativeWork > CreativeWorkSeries > Periodical> PublicationVolume > PublicationIssue
B5: Schema.org | C5: Property | D5: FRBR | E5: ELI
B6: Thing > CreativeWork | C6: ? | D6: n/a
A7: 1 | B7: CreativeWork > CreativeWorkSeries | C7: ? | D7: Work
A8: 2 | B8: CreativeWorkSeries > Periodical | C8: ? | D8: Work
A9: 3 | B9: Periodical> PublicationVolume | C9: hasPart / isPartOf | D9: Work
A10: 4 | B10: PublicationVolume > PublicationIssue | C10: hasPart / isPartOf | D10: Work | E10: LegalExpression
A11: 5
B13: Schema.org | C13: Property | D13: FRBR | E13: ELI
B14: Thing > CreativeWork | C14: subjectOf / about | D14: Work | E14: LegalResource
A15: 1 | B15: CreativeWork > Expression / LegalExpression | C15: workExample / exampleOfWork | D15: Expression | E15: LegalExpression
A16: 2
B19: Schema | C19: Property | D19: Expected Type | E19: Description
A20: Level | B20: Thing | C20: additionalType | D20: Text or URL | E20: An additional type for the item, typically used for adding more specific types from external vocabularies.
A21: 1 | B21: Thing | C21: alternateName | D21: Text | E21: An alias for the item.
A22: 1 | B22: Thing | C22: description | D22: Text or TextObject | E22: A description of the item.
A23: 1 | B23: Thing | C23: disambiguatingDescription | D23: Text | E23: A short description used to disambiguate from other, similar items.
A24: 1 | B24: Thing | C24: identifier | D24: PropertyValue, Text, or URL | E24: Any kind of identifier for any kind of Thing, such as ISBNs, GTIN codes, UUIDs, etc.
A25: 1 | B25: Thing | C25: image | D25: ImageObject or URL | E25: An image of the item.
A26: 1 | B26: Thing | C26: mainEntityOfPage | D26: CreativeWork or URL | E26: Indicates a page for which this thing is the main entity being described.
A27: 1 | B27: Thing | C27: name | D27: Text | E27: The name of the item.
A28: 1 | B28: Thing | C28: owner | D28: Organization or Person | E28: A person or organization who owns this Thing.
A29: 1 | B29: Thing | C29: potentialAction | D29: Action | E29: Indicates a potential Action, an idealized action in which this thing would play an 'object' role.
A30: 1 | B30: Thing | C30: sameAs | D30: URL | E30: URL of a reference web page that unambiguously indicates the item's identity.
A31: 1 | B31: Thing | C31: subjectOf | D31: CreativeWork or Event | E31: A CreativeWork or Event about this Thing.
A32: 1 | B32: Thing | C32: url | D32: URL | E32: URL of the item.
A33: 1
C34: 2
C35: Thing > CreativeWork
C36: Property | D36: Expected Type | E36: Description
B37: CreativeWork | C37: about | D37: Thing | E37: The subject matter of an object.
A38: 2 | B38: CreativeWork | C38: abstract | D38: Text | E38: A short description that summarizes a CreativeWork.
A39: 2 | B39: CreativeWork | C39: accessMode | D39: Text | E39: The sensory/cognitive mode through which the content can be perceived (e.g. visual, auditory).
A40: 2 | B40: CreativeWork | C40: accessModeSufficient | D40: ItemList | E40: Combined access modes that are sufficient to understand all the content.
